Traceback (most recent call last):
  File "/home/sabih/return/lib/python3.13/site-packages/jupyter_cache/executors/utils.py", line 58, in single_nb_execution
    executenb(
    ~~~~~~~~~^
        nb,
        ^^^
    ...<4 lines>...
        **kwargs,
        ^^^^^^^^^
    )
    ^
  File "/home/sabih/return/lib/python3.13/site-packages/nbclient/client.py", line 1319, in execute
    return NotebookClient(nb=nb, resources=resources, km=km, **kwargs).execute()
           ~~~~~~~~~~~~~~~~~~~~~~~~~~~~~~~~~~~~~~~~~~~~~~~~~~~~~~~~~~~~~~~~~~~^^
  File "/home/sabih/.local/lib/python3.13/site-packages/jupyter_core/utils/__init__.py", line 165, in wrapped
    return loop.run_until_complete(inner)
           ~~~~~~~~~~~~~~~~~~~~~~~^^^^^^^
  File "/home/sabih/return/lib/python3.13/asyncio/base_events.py", line 725, in run_until_complete
    return future.result()
           ~~~~~~~~~~~~~^^
  File "/home/sabih/return/lib/python3.13/site-packages/nbclient/client.py", line 709, in async_execute
    await self.async_execute_cell(
        cell, index, execution_count=self.code_cells_executed + 1
    )
  File "/home/sabih/return/lib/python3.13/site-packages/nbclient/client.py", line 1062, in async_execute_cell
    await self._check_raise_for_error(cell, cell_index, exec_reply)
  File "/home/sabih/return/lib/python3.13/site-packages/nbclient/client.py", line 918, in _check_raise_for_error
    raise CellExecutionError.from_cell_and_msg(cell, exec_reply_content)
nbclient.exceptions.CellExecutionError: An error occurred while executing the following cell:
------------------
# Laad source dataset 3

df_annual_net_earnings = pd.read_csv('dataset_sources/estat_earn_nt_net_en.csv')
df_annual_net_earings.info()
------------------


[0;31m---------------------------------------------------------------------------[0m
[0;31mNameError[0m                                 Traceback (most recent call last)
Cell [0;32mIn[7], line 4[0m
[1;32m      1[0m [38;5;66;03m# Laad source dataset 3[39;00m
[1;32m      3[0m df_annual_net_earnings [38;5;241m=[39m pd[38;5;241m.[39mread_csv([38;5;124m'[39m[38;5;124mdataset_sources/estat_earn_nt_net_en.csv[39m[38;5;124m'[39m)
[0;32m----> 4[0m [43mdf_annual_net_earings[49m[38;5;241m.[39minfo()

[0;31mNameError[0m: name 'df_annual_net_earings' is not defined

