Traceback (most recent call last):
  File "/home/May/.conda/envs/jupyterbook/lib/python3.10/site-packages/jupyter_core/utils/__init__.py", line 154, in wrapped
    asyncio.get_running_loop()
RuntimeError: no running event loop

During handling of the above exception, another exception occurred:

Traceback (most recent call last):
  File "/home/May/.conda/envs/jupyterbook/lib/python3.10/site-packages/jupyter_cache/executors/utils.py", line 58, in single_nb_execution
    executenb(
  File "/home/May/.conda/envs/jupyterbook/lib/python3.10/site-packages/nbclient/client.py", line 1319, in execute
    return NotebookClient(nb=nb, resources=resources, km=km, **kwargs).execute()
  File "/home/May/.conda/envs/jupyterbook/lib/python3.10/site-packages/jupyter_core/utils/__init__.py", line 158, in wrapped
    return loop.run_until_complete(inner)
  File "/home/May/.conda/envs/jupyterbook/lib/python3.10/asyncio/base_events.py", line 649, in run_until_complete
    return future.result()
  File "/home/May/.conda/envs/jupyterbook/lib/python3.10/site-packages/nbclient/client.py", line 709, in async_execute
    await self.async_execute_cell(
  File "/home/May/.conda/envs/jupyterbook/lib/python3.10/site-packages/nbclient/client.py", line 1062, in async_execute_cell
    await self._check_raise_for_error(cell, cell_index, exec_reply)
  File "/home/May/.conda/envs/jupyterbook/lib/python3.10/site-packages/nbclient/client.py", line 918, in _check_raise_for_error
    raise CellExecutionError.from_cell_and_msg(cell, exec_reply_content)
nbclient.exceptions.CellExecutionError: An error occurred while executing the following cell:
------------------
# df_food_prices = pd.read_csv('dataset_sources/Food_Prices.csv')
# df_food_prices_sweden = df_food_prices[df_food_prices['Country '] == 'Sweden'].drop('Country ', axis=1)
# df_food_prices_sweden.to_csv('filtered/Food_Prices_Sweden.csv', index=False)
# df_food_prices_sweden = pd.read_csv('filtered/Food_Prices_Sweden.csv')
# df_food_prices_sweden_years = df_food_prices_sweden[df_food_prices_sweden['Year '] <= 2021]
df_food_prices_sweden_years.to_csv('filtered/Food_Prices_Sweden_2018-2021', index=False)
df_food_prices_sweden.info()
# df_food_prices_sweden.describe()
df_food_prices_sweden.head(n=5)
------------------


[0;31m---------------------------------------------------------------------------[0m
[0;31mNameError[0m                                 Traceback (most recent call last)
Cell [0;32mIn[2], line 6[0m
[1;32m      1[0m [38;5;66;03m# df_food_prices = pd.read_csv('dataset_sources/Food_Prices.csv')[39;00m
[1;32m      2[0m [38;5;66;03m# df_food_prices_sweden = df_food_prices[df_food_prices['Country '] == 'Sweden'].drop('Country ', axis=1)[39;00m
[1;32m      3[0m [38;5;66;03m# df_food_prices_sweden.to_csv('filtered/Food_Prices_Sweden.csv', index=False)[39;00m
[1;32m      4[0m [38;5;66;03m# df_food_prices_sweden = pd.read_csv('filtered/Food_Prices_Sweden.csv')[39;00m
[1;32m      5[0m [38;5;66;03m# df_food_prices_sweden_years = df_food_prices_sweden[df_food_prices_sweden['Year '] <= 2021][39;00m
[0;32m----> 6[0m [43mdf_food_prices_sweden_years[49m[38;5;241m.[39mto_csv([38;5;124m'[39m[38;5;124mfiltered/Food_Prices_Sweden_2018-2021[39m[38;5;124m'[39m, index[38;5;241m=[39m[38;5;28;01mFalse[39;00m)
[1;32m      7[0m df_food_prices_sweden[38;5;241m.[39minfo()
[1;32m      8[0m [38;5;66;03m# df_food_prices_sweden.describe()[39;00m

[0;31mNameError[0m: name 'df_food_prices_sweden_years' is not defined

