Traceback (most recent call last):
  File "/home/sabih/return/lib/python3.13/site-packages/jupyter_cache/executors/utils.py", line 58, in single_nb_execution
    executenb(
    ~~~~~~~~~^
        nb,
        ^^^
    ...<4 lines>...
        **kwargs,
        ^^^^^^^^^
    )
    ^
  File "/home/sabih/return/lib/python3.13/site-packages/nbclient/client.py", line 1319, in execute
    return NotebookClient(nb=nb, resources=resources, km=km, **kwargs).execute()
           ~~~~~~~~~~~~~~~~~~~~~~~~~~~~~~~~~~~~~~~~~~~~~~~~~~~~~~~~~~~~~~~~~~~^^
  File "/home/sabih/.local/lib/python3.13/site-packages/jupyter_core/utils/__init__.py", line 165, in wrapped
    return loop.run_until_complete(inner)
           ~~~~~~~~~~~~~~~~~~~~~~~^^^^^^^
  File "/home/sabih/return/lib/python3.13/asyncio/base_events.py", line 725, in run_until_complete
    return future.result()
           ~~~~~~~~~~~~~^^
  File "/home/sabih/return/lib/python3.13/site-packages/nbclient/client.py", line 709, in async_execute
    await self.async_execute_cell(
        cell, index, execution_count=self.code_cells_executed + 1
    )
  File "/home/sabih/return/lib/python3.13/site-packages/nbclient/client.py", line 1062, in async_execute_cell
    await self._check_raise_for_error(cell, cell_index, exec_reply)
  File "/home/sabih/return/lib/python3.13/site-packages/nbclient/client.py", line 918, in _check_raise_for_error
    raise CellExecutionError.from_cell_and_msg(cell, exec_reply_content)
nbclient.exceptions.CellExecutionError: An error occurred while executing the following cell:
------------------
# All imports

import pandas as pd
import numpy as np
import seaborn as sns
import matplotlib.pyplot as plt
import plotly.graph_objs as go
import plotly.express as px
import calendar

from pyaxis import pyaxis

from plotly.offline import init_notebook_mode
init_notebook_mode(connected=True)
------------------


[31m---------------------------------------------------------------------------[39m
[31mModuleNotFoundError[39m                       Traceback (most recent call last)
[36mCell[39m[36m [39m[32mIn[1][39m[32m, line 11[39m
[32m      8[39m [38;5;28;01mimport[39;00m[38;5;250m [39m[34;01mplotly[39;00m[34;01m.[39;00m[34;01mexpress[39;00m[38;5;250m [39m[38;5;28;01mas[39;00m[38;5;250m [39m[34;01mpx[39;00m
[32m      9[39m [38;5;28;01mimport[39;00m[38;5;250m [39m[34;01mcalendar[39;00m
[32m---> [39m[32m11[39m [38;5;28;01mfrom[39;00m[38;5;250m [39m[34;01mpyaxis[39;00m[38;5;250m [39m[38;5;28;01mimport[39;00m pyaxis
[32m     13[39m [38;5;28;01mfrom[39;00m[38;5;250m [39m[34;01mplotly[39;00m[34;01m.[39;00m[34;01moffline[39;00m[38;5;250m [39m[38;5;28;01mimport[39;00m init_notebook_mode
[32m     14[39m init_notebook_mode(connected=[38;5;28;01mTrue[39;00m)

[31mModuleNotFoundError[39m: No module named 'pyaxis'

